<?xml version="1.0" encoding="utf-8"?>
<!-- This URDF was automatically created by SolidWorks to URDF Exporter! Originally created by Stephen Brawner (brawner@gmail.com) 
     Commit Version: 1.5.1-0-g916b5db  Build Version: 1.5.7152.31018
     For more information, please see http://wiki.ros.org/sw_urdf_exporter -->
<robot
  name="SLDASM">
  <link
    name="base_link">
    <inertial>
      <origin
        xyz="-2.5772E-13 -2.0178E-13 0.0029343"
        rpy="0 0 0" />
      <mass
        value="0.29247" />
      <inertia
        ixx="0.00043525"
        ixy="1.8741E-07"
        ixz="-1.2546E-17"
        iyy="0.00021502"
        iyz="1.8525E-17"
        izz="0.00064391" />
    </inertial>
    <visual>
      <origin
        xyz="0 0 0"
        rpy="0 0 0" />
      <geometry>
        <mesh
          filename="package://SLDASM/meshes/base_link.STL" />
      </geometry>
      <material
        name="">
        <color
          rgba="0.75294 0.75294 0.75294 1" />
      </material>
    </visual>
    <collision>
      <origin
        xyz="0 0 0"
        rpy="0 0 0" />
      <geometry>
        <mesh
          filename="package://SLDASM/meshes/base_link.STL" />
      </geometry>
    </collision>
  </link>
  <link
    name="Empty_Link1_1">
    <inertial>
      <origin
        xyz="-1.3878E-17 0.03 0.001894"
        rpy="0 0 0" />
      <mass
        value="0.012485" />
      <inertia
        ixx="5.692E-06"
        ixy="-4.0234E-21"
        ixz="1.8981E-21"
        iyy="7.299E-06"
        iyz="2.4588E-22"
        izz="5.692E-06" />
    </inertial>
    <visual>
      <origin
        xyz="0 0 0"
        rpy="0 0 0" />
      <geometry>
        <mesh
          filename="package://SLDASM/meshes/Empty_Link1_1.STL" />
      </geometry>
      <material
        name="">
        <color
          rgba="0.75294 0.75294 0.75294 1" />
      </material>
    </visual>
    <collision>
      <origin
        xyz="0 0 0"
        rpy="0 0 0" />
      <geometry>
        <mesh
          filename="package://SLDASM/meshes/Empty_Link1_1.STL" />
      </geometry>
    </collision>
  </link>
  <joint
    name="L1_1"
    type="revolute">
    <origin
      xyz="-0.064106 0.11911 -0.00083011"
      rpy="0 0 0.7854" />
    <parent
      link="base_link" />
    <child
      link="Empty_Link1_1" />
    <axis
      xyz="0 0 1" />
    <limit
      lower="-2.0944"
      upper="2.0944"
      effort="0"
      velocity="0" />
  </joint>
  <link
    name="Empty_Link1_2">
    <inertial>
      <origin
        xyz="2.23010497105575E-05 0.0379786312282531 0.000316026230529565"
        rpy="0 0 0" />
      <mass
        value="0.0611809794136084" />
      <inertia
        ixx="9.9543586684263E-06"
        ixy="3.72353040733886E-09"
        ixz="-2.73045208860096E-18"
        iyy="4.21625737936107E-06"
        iyz="1.97092642232907E-10"
        izz="1.00256802197203E-05" />
    </inertial>
    <visual>
      <origin
        xyz="0 0 0"
        rpy="0 0 0" />
      <geometry>
        <mesh
          filename="package://SLDASM/meshes/Empty_Link1_2.STL" />
      </geometry>
      <material
        name="">
        <color
          rgba="0.752941176470588 0.752941176470588 0.752941176470588 1" />
      </material>
    </visual>
    <collision>
      <origin
        xyz="0 0 0"
        rpy="0 0 0" />
      <geometry>
        <mesh
          filename="package://SLDASM/meshes/Empty_Link1_2.STL" />
      </geometry>
    </collision>
  </link>
  <joint
    name="L1_2"
    type="revolute">
    <origin
      xyz="0 0.06 0.001894"
      rpy="0 0 0" />
    <parent
      link="Empty_Link1_1" />
    <child
      link="Empty_Link1_2" />
    <axis
      xyz="-1 0 0" />
    <limit
      lower="-2.0944"
      upper="2.0944"
      effort="0"
      velocity="0" />
  </joint>
  <link
    name="Empty_Link1_3">
    <inertial>
      <origin
        xyz="-0.000205402388474427 0.090567333545968 0.00386969200627693"
        rpy="0 0 0" />
      <mass
        value="0.0425517722360711" />
      <inertia
        ixx="2.10424482746868E-05"
        ixy="-5.48654700730799E-12"
        ixz="3.5917796924978E-12"
        iyy="8.32040293601251E-06"
        iyz="4.63417073629606E-07"
        izz="2.49644856307801E-05" />
    </inertial>
    <visual>
      <origin
        xyz="0 0 0"
        rpy="0 0 0" />
      <geometry>
        <mesh
          filename="package://SLDASM/meshes/Empty_Link1_3.STL" />
      </geometry>
      <material
        name="">
        <color
          rgba="0.752941176470588 0.752941176470588 0.752941176470588 1" />
      </material>
    </visual>
    <collision>
      <origin
        xyz="0 0 0"
        rpy="0 0 0" />
      <geometry>
        <mesh
          filename="package://SLDASM/meshes/Empty_Link1_3.STL" />
      </geometry>
    </collision>
  </link>
  <joint
    name="L1_3"
    type="revolute">
    <origin
      xyz="0 0.075807 -9.4375E-05"
      rpy="0 0 0" />
    <parent
      link="Empty_Link1_2" />
    <child
      link="Empty_Link1_3" />
    <axis
      xyz="1 0 0" />
    <limit
      lower="-2.0944"
      upper="2.0944"
      effort="0"
      velocity="0" />
  </joint>
  <link
    name="Empty_Link2_1">
    <inertial>
      <origin
        xyz="1.34695927764225E-17 0.0299999999999999 0.0018947216847601"
        rpy="0 0 0" />
      <mass
        value="0.0124849113953182" />
      <inertia
        ixx="5.69203233862196E-06"
        ixy="-3.28180298735742E-21"
        ixz="4.23256396384778E-21"
        iyy="7.29898011192699E-06"
        iyz="-1.35354137821917E-21"
        izz="5.69203233862196E-06" />
    </inertial>
    <visual>
      <origin
        xyz="0 0 0"
        rpy="0 0 0" />
      <geometry>
        <mesh
          filename="package://SLDASM/meshes/Empty_Link2_1.STL" />
      </geometry>
      <material
        name="">
        <color
          rgba="0.752941176470588 0.752941176470588 0.752941176470588 1" />
      </material>
    </visual>
    <collision>
      <origin
        xyz="0 0 0"
        rpy="0 0 0" />
      <geometry>
        <mesh
          filename="package://SLDASM/meshes/Empty_Link2_1.STL" />
      </geometry>
    </collision>
  </link>
  <joint
    name="L2_1"
    type="revolute">
    <origin
      xyz="-0.11402 0 -0.00083078"
      rpy="0 0 1.5708" />
    <parent
      link="base_link" />
    <child
      link="Empty_Link2_1" />
    <axis
      xyz="0 0 -1" />
    <limit
      lower="-2.0944"
      upper="2.0944"
      effort="0"
      velocity="0" />
  </joint>
  <link
    name="Empty_Link2_2">
    <inertial>
      <origin
        xyz="2.23010498984379E-05 0.0379786311474948 0.000316023691016628"
        rpy="0 0 0" />
      <mass
        value="0.0611810446745335" />
      <inertia
        ixx="9.95436231766123E-06"
        ixy="3.72324998234509E-09"
        ixz="1.25933734400021E-17"
        iyy="4.21626350235731E-06"
        iyz="1.97092644321889E-10"
        izz="1.00256789520649E-05" />
    </inertial>
    <visual>
      <origin
        xyz="0 0 0"
        rpy="0 0 0" />
      <geometry>
        <mesh
          filename="package://SLDASM/meshes/Empty_Link2_2.STL" />
      </geometry>
      <material
        name="">
        <color
          rgba="0.752941176470588 0.752941176470588 0.752941176470588 1" />
      </material>
    </visual>
    <collision>
      <origin
        xyz="0 0 0"
        rpy="0 0 0" />
      <geometry>
        <mesh
          filename="package://SLDASM/meshes/Empty_Link2_2.STL" />
      </geometry>
    </collision>
  </link>
  <joint
    name="L2_2"
    type="revolute">
    <origin
      xyz="0 0.06 0.0018947"
      rpy="0 0 0" />
    <parent
      link="Empty_Link2_1" />
    <child
      link="Empty_Link2_2" />
    <axis
      xyz="1 0 0" />
    <limit
      lower="-2.0944"
      upper="2.0944"
      effort="0"
      velocity="0" />
  </joint>
  <link
    name="Empty_Link2_3">
    <inertial>
      <origin
        xyz="-0.000205402445964697 0.090567316894586 0.00386969252647781"
        rpy="0 0 0" />
      <mass
        value="0.0425517593525127" />
      <inertia
        ixx="2.10424482015851E-05"
        ixy="-6.76801899948424E-12"
        ixz="4.10359245204323E-12"
        iyy="8.3204062259025E-06"
        iyz="4.63417591478139E-07"
        izz="2.49644888893537E-05" />
    </inertial>
    <visual>
      <origin
        xyz="0 0 0"
        rpy="0 0 0" />
      <geometry>
        <mesh
          filename="package://SLDASM/meshes/Empty_Link2_3.STL" />
      </geometry>
      <material
        name="">
        <color
          rgba="0.752941176470588 0.752941176470588 0.752941176470588 1" />
      </material>
    </visual>
    <collision>
      <origin
        xyz="0 0 0"
        rpy="0 0 0" />
      <geometry>
        <mesh
          filename="package://SLDASM/meshes/Empty_Link2_3.STL" />
      </geometry>
    </collision>
  </link>
  <joint
    name="L2_3"
    type="revolute">
    <origin
      xyz="0 0.075807 -9.4375E-05"
      rpy="0 0 0" />
    <parent
      link="Empty_Link2_2" />
    <child
      link="Empty_Link2_3" />
    <axis
      xyz="1 0 0" />
    <limit
      lower="-2.0944"
      upper="2.0944"
      effort="0"
      velocity="0" />
  </joint>
  <link
    name="Empty_Link3_1">
    <inertial>
      <origin
        xyz="-2.77555756156289E-17 0.03 0.00116802137717336"
        rpy="0 0 0" />
      <mass
        value="0.0124849113953182" />
      <inertia
        ixx="5.69203233862196E-06"
        ixy="-2.75285707857648E-21"
        ixz="3.40833949687794E-21"
        iyy="7.29898011192699E-06"
        iyz="-4.51178446103114E-21"
        izz="5.69203233862197E-06" />
    </inertial>
    <visual>
      <origin
        xyz="0 0 0"
        rpy="0 0 0" />
      <geometry>
        <mesh
          filename="package://SLDASM/meshes/Empty_Link3_1.STL" />
      </geometry>
      <material
        name="">
        <color
          rgba="0.752941176470588 0.752941176470588 0.752941176470588 1" />
      </material>
    </visual>
    <collision>
      <origin
        xyz="0 0 0"
        rpy="0 0 0" />
      <geometry>
        <mesh
          filename="package://SLDASM/meshes/Empty_Link3_1.STL" />
      </geometry>
    </collision>
  </link>
  <joint
    name="L3_1"
    type="revolute">
    <origin
      xyz="-0.064106 -0.11911 -0.00010408"
      rpy="0 0 2.3562" />
    <parent
      link="base_link" />
    <child
      link="Empty_Link3_1" />
    <axis
      xyz="0 0 -1" />
    <limit
      lower="-2.0944"
      upper="2.0944"
      effort="0"
      velocity="0" />
  </joint>
  <link
    name="Empty_Link3_2">
    <inertial>
      <origin
        xyz="2.23010495962045E-05 0.0379786312284709 0.00031602623055808"
        rpy="0 0 0" />
      <mass
        value="0.0611809794132485" />
      <inertia
        ixx="9.95435866842593E-06"
        ixy="3.72353040909264E-09"
        ixz="-1.15343432344502E-17"
        iyy="4.21625737934612E-06"
        iyz="1.97092640729349E-10"
        izz="1.00256802197127E-05" />
    </inertial>
    <visual>
      <origin
        xyz="0 0 0"
        rpy="0 0 0" />
      <geometry>
        <mesh
          filename="package://SLDASM/meshes/Empty_Link3_2.STL" />
      </geometry>
      <material
        name="">
        <color
          rgba="0.752941176470588 0.752941176470588 0.752941176470588 1" />
      </material>
    </visual>
    <collision>
      <origin
        xyz="0 0 0"
        rpy="0 0 0" />
      <geometry>
        <mesh
          filename="package://SLDASM/meshes/Empty_Link3_2.STL" />
      </geometry>
    </collision>
  </link>
  <joint
    name="L3_2"
    type="revolute">
    <origin
      xyz="0 0.06 0.001168"
      rpy="0 0 0" />
    <parent
      link="Empty_Link3_1" />
    <child
      link="Empty_Link3_2" />
    <axis
      xyz="1 0 0" />
    <limit
      lower="-2.0944"
      upper="2.0944"
      effort="0"
      velocity="0" />
  </joint>
  <link
    name="Empty_Link3_3">
    <inertial>
      <origin
        xyz="-0.000205401933015534 0.0903278126993768 0.00763559797177255"
        rpy="0 0 0" />
      <mass
        value="0.0425517702502532" />
      <inertia
        ixx="2.10424482178194E-05"
        ixy="-5.8767108543291E-12"
        ixz="3.32951603119302E-12"
        iyy="8.31069191683203E-06"
        iyz="-2.30286618475183E-07"
        izz="2.49741964470486E-05" />
    </inertial>
    <visual>
      <origin
        xyz="0 0 0"
        rpy="0 0 0" />
      <geometry>
        <mesh
          filename="package://SLDASM/meshes/Empty_Link3_3.STL" />
      </geometry>
      <material
        name="">
        <color
          rgba="0.752941176470588 0.752941176470588 0.752941176470588 1" />
      </material>
    </visual>
    <collision>
      <origin
        xyz="0 0 0"
        rpy="0 0 0" />
      <geometry>
        <mesh
          filename="package://SLDASM/meshes/Empty_Link3_3.STL" />
      </geometry>
    </collision>
  </link>
  <joint
    name="L3_3"
    type="revolute">
    <origin
      xyz="0 0.075807 -9.4375E-05"
      rpy="0 0 0" />
    <parent
      link="Empty_Link3_2" />
    <child
      link="Empty_Link3_3" />
    <axis
      xyz="1 0 0" />
    <limit
      lower="-2.0944"
      upper="2.0944"
      effort="0"
      velocity="0" />
  </joint>
  <link
    name="Empty_Link4_1">
    <inertial>
      <origin
        xyz="-1.38777878078145E-17 0.03 0.000233833743558315"
        rpy="0 0 0" />
      <mass
        value="0.0124849113953182" />
      <inertia
        ixx="5.69203233862196E-06"
        ixy="-2.5410988417629E-21"
        ixz="4.09844305011973E-21"
        iyy="7.29898011192698E-06"
        iyz="3.89192643657554E-21"
        izz="5.69203233862196E-06" />
    </inertial>
    <visual>
      <origin
        xyz="0 0 0"
        rpy="0 0 0" />
      <geometry>
        <mesh
          filename="package://SLDASM/meshes/Empty_Link4_1.STL" />
      </geometry>
      <material
        name="">
        <color
          rgba="0.752941176470588 0.752941176470588 0.752941176470588 1" />
      </material>
    </visual>
    <collision>
      <origin
        xyz="0 0 0"
        rpy="0 0 0" />
      <geometry>
        <mesh
          filename="package://SLDASM/meshes/Empty_Link4_1.STL" />
      </geometry>
    </collision>
  </link>
  <joint
    name="L4_1"
    type="revolute">
    <origin
      xyz="0.064106 -0.11911 0.00083011"
      rpy="0 0 -2.3562" />
    <parent
      link="base_link" />
    <child
      link="Empty_Link4_1" />
    <axis
      xyz="0 0 1" />
    <limit
      lower="-2.0944"
      upper="2.0944"
      effort="0"
      velocity="0" />
  </joint>
  <link
    name="Empty_Link4_2">
    <inertial>
      <origin
        xyz="2.23010496335774E-05 0.0379786312280972 0.000316026230530893"
        rpy="0 0 0" />
      <mass
        value="0.0611809794141035" />
      <inertia
        ixx="9.9543586685095E-06"
        ixy="3.72353041380998E-09"
        ixz="9.75178198132672E-19"
        iyy="4.21625737936793E-06"
        iyz="1.97092631289633E-10"
        izz="1.00256802198048E-05" />
    </inertial>
    <visual>
      <origin
        xyz="0 0 0"
        rpy="0 0 0" />
      <geometry>
        <mesh
          filename="package://SLDASM/meshes/Empty_Link4_2.STL" />
      </geometry>
      <material
        name="">
        <color
          rgba="0.752941176470588 0.752941176470588 0.752941176470588 1" />
      </material>
    </visual>
    <collision>
      <origin
        xyz="0 0 0"
        rpy="0 0 0" />
      <geometry>
        <mesh
          filename="package://SLDASM/meshes/Empty_Link4_2.STL" />
      </geometry>
    </collision>
  </link>
  <joint
    name="L4_2"
    type="revolute">
    <origin
      xyz="0 0.06 0.00023383"
      rpy="0 0 0" />
    <parent
      link="Empty_Link4_1" />
    <child
      link="Empty_Link4_2" />
    <axis
      xyz="-1 0 0" />
    <limit
      lower="-2.0944"
      upper="2.0944"
      effort="0"
      velocity="0" />
  </joint>
  <link
    name="Empty_Link4_3">
    <inertial>
      <origin
        xyz="-0.000205402388474163 0.0905673335459682 0.00386969200627698"
        rpy="0 0 0" />
      <mass
        value="0.0425517722360712" />
      <inertia
        ixx="2.10424482746869E-05"
        ixy="-5.4865470102726E-12"
        ixz="3.59177969120469E-12"
        iyy="8.32040293601252E-06"
        iyz="4.63417073629614E-07"
        izz="2.49644856307801E-05" />
    </inertial>
    <visual>
      <origin
        xyz="0 0 0"
        rpy="0 0 0" />
      <geometry>
        <mesh
          filename="package://SLDASM/meshes/Empty_Link4_3.STL" />
      </geometry>
      <material
        name="">
        <color
          rgba="0.752941176470588 0.752941176470588 0.752941176470588 1" />
      </material>
    </visual>
    <collision>
      <origin
        xyz="0 0 0"
        rpy="0 0 0" />
      <geometry>
        <mesh
          filename="package://SLDASM/meshes/Empty_Link4_3.STL" />
      </geometry>
    </collision>
  </link>
  <joint
    name="L4_3"
    type="revolute">
    <origin
      xyz="0 0.075807 -9.4375E-05"
      rpy="0 0 0" />
    <parent
      link="Empty_Link4_2" />
    <child
      link="Empty_Link4_3" />
    <axis
      xyz="1 0 0" />
    <limit
      lower="-2.0944"
      upper="2.0944"
      effort="0"
      velocity="0" />
  </joint>
  <link
    name="Empty_Link5_1">
    <inertial>
      <origin
        xyz="1.85224882579531E-18 0.03 0.00023316064417904"
        rpy="0 0 0" />
      <mass
        value="0.0124849113953182" />
      <inertia
        ixx="5.69203233862196E-06"
        ixy="3.13865716785285E-21"
        ixz="3.20223988755161E-21"
        iyy="7.29898011192699E-06"
        iyz="1.78621756718691E-21"
        izz="5.69203233862196E-06" />
    </inertial>
    <visual>
      <origin
        xyz="0 0 0"
        rpy="0 0 0" />
      <geometry>
        <mesh
          filename="package://SLDASM/meshes/Empty_Link5_1.STL" />
      </geometry>
      <material
        name="">
        <color
          rgba="0.752941176470588 0.752941176470588 0.752941176470588 1" />
      </material>
    </visual>
    <collision>
      <origin
        xyz="0 0 0"
        rpy="0 0 0" />
      <geometry>
        <mesh
          filename="package://SLDASM/meshes/Empty_Link5_1.STL" />
      </geometry>
    </collision>
  </link>
  <joint
    name="L5_1"
    type="revolute">
    <origin
      xyz="0.11402 0 0.00083078"
      rpy="0 0 -1.5708" />
    <parent
      link="base_link" />
    <child
      link="Empty_Link5_1" />
    <axis
      xyz="0 0 1" />
    <limit
      lower="-2.0944"
      upper="2.0944"
      effort="0"
      velocity="0" />
  </joint>
  <link
    name="Empty_Link5_2">
    <inertial>
      <origin
        xyz="2.23010497450384E-05 0.0379786311477796 0.000316023691054129"
        rpy="0 0 0" />
      <mass
        value="0.0611810446740645" />
      <inertia
        ixx="9.95436231766076E-06"
        ixy="3.72324998456517E-09"
        ixz="3.03485752148019E-20"
        iyy="4.21626350233521E-06"
        iyz="1.97092642536007E-10"
        izz="1.00256789520525E-05" />
    </inertial>
    <visual>
      <origin
        xyz="0 0 0"
        rpy="0 0 0" />
      <geometry>
        <mesh
          filename="package://SLDASM/meshes/Empty_Link5_2.STL" />
      </geometry>
      <material
        name="">
        <color
          rgba="0.752941176470588 0.752941176470588 0.752941176470588 1" />
      </material>
    </visual>
    <collision>
      <origin
        xyz="0 0 0"
        rpy="0 0 0" />
      <geometry>
        <mesh
          filename="package://SLDASM/meshes/Empty_Link5_2.STL" />
      </geometry>
    </collision>
  </link>
  <joint
    name="L5_2"
    type="revolute">
    <origin
      xyz="0 0.06 0.00023316"
      rpy="0 0 0" />
    <parent
      link="Empty_Link5_1" />
    <child
      link="Empty_Link5_2" />
    <axis
      xyz="-1 0 0" />
    <limit
      lower="-2.0944"
      upper="2.0944"
      effort="0"
      velocity="0" />
  </joint>
  <link
    name="Empty_Link5_3">
    <inertial>
      <origin
        xyz="-0.000205402445964644 0.090567316894586 0.00386969252647787"
        rpy="0 0 0" />
      <mass
        value="0.0425517593525128" />
      <inertia
        ixx="2.1042448201585E-05"
        ixy="-6.76801899725818E-12"
        ixz="4.10359244625057E-12"
        iyy="8.32040622590251E-06"
        iyz="4.63417591478128E-07"
        izz="2.49644888893537E-05" />
    </inertial>
    <visual>
      <origin
        xyz="0 0 0"
        rpy="0 0 0" />
      <geometry>
        <mesh
          filename="package://SLDASM/meshes/Empty_Link5_3.STL" />
      </geometry>
      <material
        name="">
        <color
          rgba="0.752941176470588 0.752941176470588 0.752941176470588 1" />
      </material>
    </visual>
    <collision>
      <origin
        xyz="0 0 0"
        rpy="0 0 0" />
      <geometry>
        <mesh
          filename="package://SLDASM/meshes/Empty_Link5_3.STL" />
      </geometry>
    </collision>
  </link>
  <joint
    name="L5_3"
    type="revolute">
    <origin
      xyz="0 0.075807 -9.4375E-05"
      rpy="0 0 0" />
    <parent
      link="Empty_Link5_2" />
    <child
      link="Empty_Link5_3" />
    <axis
      xyz="1 0 0" />
    <limit
      lower="-2.0944"
      upper="2.0944"
      effort="0"
      velocity="0" />
  </joint>
  <link
    name="Empty_Link6_1">
    <inertial>
      <origin
        xyz="0 0 0"
        rpy="0 0 0" />
      <mass
        value="0" />
      <inertia
        ixx="0"
        ixy="0"
        ixz="0"
        iyy="0"
        iyz="0"
        izz="0" />
    </inertial>
    <visual>
      <origin
        xyz="0 0 0"
        rpy="0 0 0" />
      <geometry>
        <mesh
          filename="package://SLDASM/meshes/Empty_Link6_1.STL" />
      </geometry>
      <material
        name="">
        <color
          rgba="1 1 1 1" />
      </material>
    </visual>
    <collision>
      <origin
        xyz="0 0 0"
        rpy="0 0 0" />
      <geometry>
        <mesh
          filename="package://SLDASM/meshes/Empty_Link6_1.STL" />
      </geometry>
    </collision>
  </link>
  <joint
    name="L6_1"
    type="revolute">
    <origin
      xyz="0.064106 0.11911 0.00010408"
      rpy="0 0 -0.7854" />
    <parent
      link="base_link" />
    <child
      link="Empty_Link6_1" />
    <axis
      xyz="0 0 1" />
    <limit
      lower="-2.0944"
      upper="2.0944"
      effort="0"
      velocity="0" />
  </joint>
  <link
    name="Empty_Link6_2">
    <inertial>
      <origin
        xyz="2.23010497450576E-05 0.0379786312281867 0.000316026230520652"
        rpy="0 0 0" />
      <mass
        value="0.0611809794137163" />
      <inertia
        ixx="9.95435866842633E-06"
        ixy="3.7235304069901E-09"
        ixz="3.2649164671794E-20"
        iyy="4.21625737936564E-06"
        iyz="1.97092642538275E-10"
        izz="1.00256802197224E-05" />
    </inertial>
    <visual>
      <origin
        xyz="0 0 0"
        rpy="0 0 0" />
      <geometry>
        <mesh
          filename="package://SLDASM/meshes/Empty_Link6_2.STL" />
      </geometry>
      <material
        name="">
        <color
          rgba="0.752941176470588 0.752941176470588 0.752941176470588 1" />
      </material>
    </visual>
    <collision>
      <origin
        xyz="0 0 0"
        rpy="0 0 0" />
      <geometry>
        <mesh
          filename="package://SLDASM/meshes/Empty_Link6_2.STL" />
      </geometry>
    </collision>
  </link>
  <joint
    name="L6_2"
    type="revolute">
    <origin
      xyz="0 0.06 0.00095986"
      rpy="0 0 0" />
    <parent
      link="Empty_Link6_1" />
    <child
      link="Empty_Link6_2" />
    <axis
      xyz="-1 0 0" />
    <limit
      lower="-2.0944"
      upper="2.0944"
      effort="0"
      velocity="0" />
  </joint>
  <link
    name="Empty_Link6_3">
    <inertial>
      <origin
        xyz="-0.00020540238847426 0.0905673335459682 0.00386969200627693"
        rpy="0 0 0" />
      <mass
        value="0.0425517722360711" />
      <inertia
        ixx="2.10424482746868E-05"
        ixy="-5.48654700222579E-12"
        ixz="3.59177969138059E-12"
        iyy="8.32040293601252E-06"
        iyz="4.63417073629613E-07"
        izz="2.49644856307801E-05" />
    </inertial>
    <visual>
      <origin
        xyz="0 0 0"
        rpy="0 0 0" />
      <geometry>
        <mesh
          filename="package://SLDASM/meshes/Empty_Link6_3.STL" />
      </geometry>
      <material
        name="">
        <color
          rgba="0.752941176470588 0.752941176470588 0.752941176470588 1" />
      </material>
    </visual>
    <collision>
      <origin
        xyz="0 0 0"
        rpy="0 0 0" />
      <geometry>
        <mesh
          filename="package://SLDASM/meshes/Empty_Link6_3.STL" />
      </geometry>
    </collision>
  </link>
  <joint
    name="L6_3"
    type="revolute">
    <origin
      xyz="0 0.075807 -9.4375E-05"
      rpy="0 0 0" />
    <parent
      link="Empty_Link6_2" />
    <child
      link="Empty_Link6_3" />
    <axis
      xyz="1 0 0" />
    <limit
      lower="-2.0944"
      upper="2.0944"
      effort="0"
      velocity="0" />
  </joint>
</robot>